#модуль #python #asyncio #асинхронное_программирование

В целом главным оружием для борьбы с исключениями как и раньше являются прямые руки, но если с этим не задалось, структура `try-except` по-прежнему работает, если не знаешь что это иди, читай [[try-except|тут]]
### Примеры обработки исключений в задачах
```python
import asyncio

async def task_with_exception():
    print("Начало выполнения задачи")
    await asyncio.sleep(2)
    raise ValueError("Произошла ошибка")
    print("Задача выполнена")

async def main():
    task = asyncio.create_task(task_with_exception())
    
    try:
        await task
    except ValueError as e:
        print(f"Обработано исключение: {e}")

asyncio.run(main())
```
```
Начало выполнения задачи
Обработано исключение: Произошла ошибка
```
В этом примере:
- **Исключение в задаче**: Внутри `task_with_exception` выбрасывается `ValueError` после 2 секунд ожидания.
- **Обработка исключения**: В функции `main` мы создаем задачу и ожидаем ее завершения внутри блока `try`. Если задача выбрасывает исключение, оно перехватывается в блоке `except`, и мы выводим сообщение об ошибке.
### Исключения и `asyncio.gather`
Функция `asyncio.gather` может обрабатывать несколько задач одновременно. Если одна из задач выбрасывает исключение, оно также будет обработано. Рассмотрим пример:
```python
import asyncio

async def task1():
    await asyncio.sleep(1)
    print("Задача 1 завершена")
    return "Результат 1"

async def task2():
    await asyncio.sleep(2)
    raise ValueError("Ошибка в задаче 2")

async def main():
    try:
        results = await asyncio.gather(task1(), task2())
        print(results)
    except ValueError as e:
        print(f"Обработано исключение: {e}")

asyncio.run(main())
```
```
Задача 1 завершена
Обработано исключение: Ошибка в задаче 2
```
В этом примере:
- **Исключение в** `asyncio.gather`: `task2` выбрасывает `ValueError`. Это исключение перехватывается в блоке `except` внутри `main`.
- **Результаты задач**: Если одна из задач выбрасывает исключение, `asyncio.gather` также завершится с ошибкой.
### Исключения и `asyncio.wait`
Когда функция `asyncio.wait` используется для ожидания завершения задач, задачи, в которых возникают исключения, попадают в множество `done`. Задачи в этом множестве могут быть завершены успешно или завершены с исключением. Для проверки наличия исключений используется метод `task.exception()`.
```python
import asyncio

async def task1():
    await asyncio.sleep(1)
    return "Результат задачи №1"

async def task2():
    await asyncio.sleep(1)
    raise ValueError("Ошибка в задаче 2")

async def main():
    tasks = [asyncio.create_task(task1()), asyncio.create_task(task2())]

    done, pending = await asyncio.wait(tasks, return_when=asyncio.ALL_COMPLETED)

    for task in done:
        if task.exception():
            print(f"Обработано исключение: {task.exception()}")
        else:
            print(f"Результат: {task.result()}")

asyncio.run(main())
```
В этом примере:
- **Множество** `done`: Задачи с исключениями, такие как `task2`, попадают в множество `done`, так как они завершились (хотя и с ошибками).
- **Проверка исключений**: Метод `task.exception()` используется для проверки наличия исключений и их обработки.